<?xml version="1.0"?>
<robot name="marm" xmlns:xacro="http://www.ros.org/wiki/xacro">
    <!-- Defining the colors used in this robot -->
    <material name="Black">
        <color rgba="0 0 0 1"/>
    </material>
    <material name="White">
        <color rgba="1 1 1 1"/>
    </material>
    <material name="Blue">
        <color rgba="0 0 1 1"/>
    </material>
    <material name="Red">
        <color rgba="1 0 0 1"/>
    </material>

    <!-- World link -->
    <link name="world" />


    <!-- Constants -->
    <xacro:property name="M_PI" value="3.14159"/>

    <!-- link1 properties -->
    <xacro:property name="link0_radius" value="0.05"/>
    <xacro:property name="link0_length" value="0.04"/>
    <xacro:property name="link0_mass" value="1"/>

    <!-- link1 properties -->
    <xacro:property name="link1_radius" value="0.03"/>
    <xacro:property name="link1_length" value="0.12"/>
    <xacro:property name="link1_mass" value="1"/>

    <!-- link2 properties -->
    <xacro:property name="link2_radius" value="0.03"/>
    <xacro:property name="link2_length" value="0.14"/>
    <xacro:property name="link2_mass" value="0.8"/>

    <!-- link3 properties -->
    <xacro:property name="link3_radius" value="0.03"/>
    <xacro:property name="link3_length" value="0.15"/>
    <xacro:property name="link3_mass" value="0.8"/>

    <!-- link4 properties -->
    <xacro:property name="link4_radius" value="0.025"/>
    <xacro:property name="link4_length" value="0.06"/>
    <xacro:property name="link4_mass" value="0.7"/>

    <!-- link5 properties -->
    <xacro:property name="link5_radius" value="0.03"/>
    <xacro:property name="link5_length" value="0.06"/>
    <xacro:property name="link5_mass" value="0.7"/>

    <!-- link6 properties -->
    <xacro:property name="link6_radius" value="0.04" />
    <xacro:property name="link6_length" value="0.02" />
    <xacro:property name="link6_mass" value="0.6" />

    <!-- gripper -->
    <xacro:property name="gripper_length" value="0.03" />
    <xacro:property name="gripper_width" value="0.01" />
    <xacro:property name="gripper_height" value="0.06" />
    <xacro:property name="gripper_mass" value="0.5" />

    <!-- Gripper frame -->
    <xacro:property name="grasp_frame_radius" value="0.001" />

    <!-- ////////////////////////////////////// ARM BASE ////////////////////////////////////// -->
    <joint name="world_arm_joint" type="fixed">
        <origin xyz="0 0 0" rpy="0 0 0" />
        <parent link="world"/>
        <child link="base_link" />
    </joint>

    <link name="base_link">
        <visual>
            <origin xyz="0 0 0" rpy="0 0 0" />
            <geometry>
                <box size="0.001 0.001 0.001" />
            </geometry>
        </visual>

        <collision>
            <geometry>
            <box size="0.001 0.001 0.001"/>
            </geometry>
        </collision>

        <inertial>
            <origin xyz="0 0 0" rpy="0 0 0" />
            <mass value="0.1" />
            <inertia ixx="0.0001" ixy="0" ixz="0" iyy="0.0001" iyz="0" izz="0.0001" />
        </inertial>
    </link>

    <joint name="base_joint" type="fixed">
        <origin xyz="0 0 ${link0_length/2}" rpy="0 0 0" />
        <parent link="base_link"/>
        <child link="link0" />
    </joint>

    <!-- ////////////////////////////////////// LINK0 ////////////////////////////////////// -->
    <link name="link0">
        <visual>
            <origin xyz="0 0 0" rpy="0 0 0" />
            <geometry>
                <cylinder radius="${link0_radius}" length="${link0_length}"/>
            </geometry>
            <material name="White" />
        </visual>
        <collision>
            <origin xyz="0 0 0" rpy="0 0 0" />
            <geometry>
                <cylinder radius="${link0_radius}" length="${link0_length}"/>
            </geometry>
        </collision>
        <inertial>
            <origin xyz="0 0 0" rpy="0 0 0" />
            <mass value="${link0_mass}" />
            <inertia ixx="${link0_mass * (3 * link0_radius ** 2 + link0_length ** 2) / 12}" ixy="0" ixz="0" iyy="${link0_mass * (3 * link0_radius ** 2 + link0_length ** 2) / 12}" iyz="0" izz="${link0_mass * link0_radius ** 2 / 2}" />
        </inertial>
    </link>

    <joint name="joint1" type="revolute">
        <parent link="link0"/>
        <child link="link1"/>
        <origin xyz="0 0 ${link0_length/2}" rpy="0 ${M_PI/2} 0" />
        <axis xyz="-1 0 0" />
        <limit effort="300" velocity="1" lower="${-M_PI}" upper="${M_PI}"/>
    </joint>


    <!-- ////////////////////////////////////// LINK1 ////////////////////////////////////// -->
    <link name="link1" >
        <visual>
            <origin xyz="-${link1_length/2} 0 0" rpy="0 ${M_PI/2} 0" />
            <geometry>
                <cylinder radius="${link1_radius}" length="${link1_length}"/>
            </geometry>
            <material name="Blue" />
        </visual>
        <collision>
            <origin xyz="-${link1_length/2} 0 0" rpy="0 ${M_PI/2} 0" />
            <geometry>
                <cylinder radius="${link1_radius}" length="${link1_length}"/>
            </geometry>
        </collision>
        <inertial>
            <origin xyz="-${link1_length/2} 0 0" rpy="0 ${M_PI/2} 0" />
            <mass value="${link1_mass}" />
            <inertia ixx="${link1_mass * link1_radius ** 2 / 2}" ixy="0" ixz="0" iyy="${link1_mass * (3 * link1_radius ** 2 + link1_length ** 2) / 12}" iyz="0" izz="${link1_mass * (3 * link1_radius ** 2 + link1_length ** 2) / 12}" />
        </inertial>
    </link>

    <joint name="joint2" type="revolute">
        <parent link="link1"/>
        <child link="link2"/>
        <origin xyz="-${link1_length} 0 0.0" rpy="-${M_PI/2} 0 ${M_PI/2}" />
        <axis xyz="1 0 0" />
        <limit effort="300" velocity="1" lower="${-M_PI}" upper="${M_PI}" />
    </joint>

    <!-- ////////////////////////////////////// LINK2 ////////////////////////////////////// -->
    <link name="link2" >
        <visual>
            <origin xyz="0 0 ${link2_length/2}" rpy="0 0 0" />
            <geometry>
                <cylinder radius="${link2_radius}" length="${link2_length}"/>
            </geometry>
            <material name="White" />
        </visual>

        <collision>
            <origin xyz="0 0 ${link2_length/2}" rpy="0 0 0" />
            <geometry>
                <cylinder radius="${link2_radius}" length="${link2_length}"/>
            </geometry>
        </collision>
        <inertial>
            <origin xyz="0 0 ${link2_length/2}" rpy="0 0 0" />
            <mass value="${link2_mass}" />
            <inertia ixx="${link2_mass * (3 * link2_radius ** 2 + link2_length ** 2) / 12}" ixy="0" ixz="0" iyy="${link2_mass * (3 * link2_radius ** 2 + link2_length ** 2) / 12}" iyz="0" izz="${link2_mass * link2_radius ** 2 / 2}" />
        </inertial>
    </link>

    <joint name="joint3" type="revolute">
        <parent link="link2"/>
        <child link="link3"/>
        <origin xyz="0 0 ${link2_length}" rpy="0 ${M_PI} 0" />
        <axis xyz="-1 0 0" />
        <limit effort="300" velocity="1" lower="${-M_PI}" upper="${M_PI}" />
    </joint>

    <!-- ////////////////////////////////////// LINK3 ////////////////////////////////////// -->
    <link name="link3" >
        <visual>
            <origin xyz="0 0 -${link3_length/2}" rpy="0 0 0" />
            <geometry>
                <cylinder radius="${link3_radius}" length="${link3_length}"/>
            </geometry>
            <material name="Blue" />
        </visual>
        <collision>
            <origin xyz="0 0 -${link3_length/2}" rpy="0 0 0" />
            <geometry>
                <cylinder radius="${link3_radius}" length="${link3_length}"/>
            </geometry>
        </collision>
        <inertial>
            <origin xyz="0 0 -${link3_length/2}" rpy="0 0 0" />
            <mass value="${link3_mass}" />
            <inertia ixx="${link3_mass * (3 * link3_radius ** 2 + link3_length ** 2) / 12}" ixy="0" ixz="0" iyy="${link3_mass * (3 * link3_radius ** 2 + link3_length ** 2) / 12}" iyz="0" izz="${link3_mass * link3_radius ** 2 / 2}" />
        </inertial>
    </link>

    <joint name="joint4" type="revolute">
        <parent link="link3"/>
        <child link="link4"/>
        <origin xyz="0.0 0.0 -${link3_length}" rpy="0 ${M_PI/2} ${M_PI}" />
        <axis xyz="1 0 0" />
        <limit effort="300" velocity="1" lower="${-M_PI}" upper="${M_PI}" />
    </joint>

    <!-- ////////////////////////////////////// LINK4 ////////////////////////////////////// -->
    <link name="link4" >
        <visual>
            <origin xyz="${link4_length/2} 0 0" rpy="0 ${M_PI/2} 0" />
            <geometry>
                <cylinder radius="${link4_radius}" length="${link4_length}"/>
            </geometry>
            <material name="Black" />
        </visual>
        <collision>
            <origin xyz="${link4_length/2} 0 0" rpy="0 ${M_PI/2} 0" />
            <geometry>
                <cylinder radius="${link4_radius}" length="${link4_length}"/>
            </geometry>
        </collision>
        <inertial>
            <origin xyz="${link4_length/2} 0 0" rpy="0 ${M_PI/2} 0" />
            <mass value="${link4_mass}" />
            <inertia ixx="${link4_mass * link4_radius ** 2 / 2}" ixy="0" ixz="0" iyy="${link4_mass * (3 * link4_radius ** 2 + link4_length ** 2) / 12}" iyz="0" izz="${link4_mass * (3 * link4_radius ** 2 + link4_length ** 2) / 12}" />
        </inertial>
    </link>

    <joint name="joint5" type="revolute">
        <parent link="link4"/>
        <child link="link5"/>
        <origin xyz="${link4_length} 0.0 0.0" rpy="0 ${M_PI/2} 0" />
        <axis xyz="1 0 0" />
        <limit effort="300" velocity="1" lower="${-M_PI}" upper="${M_PI}" />
    </joint>

    <!-- ////////////////////////////////////// LINK5 ////////////////////////////////////// -->
    <link name="link5">
        <visual>
            <origin xyz="0 0 ${link4_length/2}" rpy="0 0 0" />
            <geometry>
                <cylinder radius="${link5_radius}" length="${link5_length}"/>
            </geometry>
            <material name="White" />
        </visual>
        <collision>
            <origin xyz="0 0 ${link4_length/2} " rpy="0 0 0" />
            <geometry>
                <cylinder radius="${link5_radius}" length="${link5_length}"/>
            </geometry>
        </collision>
        <inertial>
            <origin xyz="0 0 ${link4_length/2}" rpy="0 0 0" />
            <mass value="${link5_mass}" />
            <inertia ixx="${link5_mass * (3 * link5_radius ** 2 + link5_length ** 2) / 12}" ixy="0" ixz="0" iyy="${link5_mass * (3 * link5_radius ** 2 + link5_length ** 2) / 12}" iyz="0" izz="${link5_mass * link5_radius ** 2 / 2}" />
        </inertial>
    </link>

    <joint name="joint6" type="revolute">
        <parent link="link5"/>
        <child link="link6"/>
        <origin xyz="0 0 ${link4_length}" rpy="${1.5*M_PI} -${M_PI/2} 0" />
        <axis xyz="1 0 0" />
        <limit effort="300" velocity="1" lower="${-2*M_PI}" upper="${2*M_PI}" />
    </joint>

    <!-- ////////////////////////////////////// LINK6 ////////////////////////////////////// -->
    <link name="link6">
        <visual>
            <origin xyz="${link6_length/2} 0 0 " rpy="0 ${M_PI/2} 0" />
            <geometry>
                <cylinder radius="${link6_radius}" length="${link6_length}"/>
            </geometry>
            <material name="Blue" />
        </visual>
        <collision>
            <origin xyz="${link6_length/2} 0 0" rpy="0 ${M_PI/2} 0" />
            <geometry>
                <cylinder radius="${link6_radius}" length="${link6_length}"/>
            </geometry>
        </collision>
        <inertial>
            <origin xyz="${link6_length/2} 0 0" rpy="0 ${M_PI/2} 0" />
            <mass value="${link6_mass}" />
            <inertia ixx="${link6_mass * link6_radius ** 2 / 2}" ixy="0" ixz="0" iyy="${link6_mass * (3 * link6_radius ** 2 + link6_length ** 2) / 12}" iyz="0" izz="${link6_mass * (3 * link6_radius ** 2 + link6_length ** 2) / 12}" />
        </inertial>
    </link>

    <joint name="finger_joint1" type="prismatic">
        <parent link="link6"/>
        <child link="gripper_finger_link1"/>
        <origin xyz="${link6_length} -0.03 0" rpy="0 0 0" />
        <axis xyz="0 1 0" />
        <limit effort="100" lower="0" upper="0.06" velocity="0.02"/>
    </joint>

    <!-- ////////////////////////////////////// gripper ////////////////////////////////////// -->
    <!-- LEFT GRIPPER AFT LINK -->
    <link name="gripper_finger_link1">
        <visual>
            <origin xyz="${gripper_height/2} 0 0" rpy="0 ${M_PI/2} 0" />
            <geometry>
                <box size="${gripper_length} ${gripper_width} ${gripper_height}" />
            </geometry>
            <material name="White" />
        </visual>
        <collision>
            <origin xyz="${gripper_height/2} 0 0" rpy="0 ${M_PI/2} 0" />
            <geometry>
                <box size="${gripper_length} ${gripper_width} ${gripper_height}" />
            </geometry>
        </collision>
        <inertial>
            <origin xyz="${gripper_height/2} 0 0" rpy="0 ${M_PI/2} 0" />
            <mass value="${gripper_mass}" />
            <inertia ixx="${gripper_mass * (gripper_width ** 2 + gripper_height ** 2) / 12}" ixy="0" ixz="0" iyy="${gripper_mass * (gripper_length ** 2 + gripper_height ** 2) / 12}" iyz="0" izz="${gripper_mass * (gripper_length ** 2 + gripper_width ** 2) / 12}" />
        </inertial>
    </link>

    <joint name="finger_joint2" type="fixed">
        <parent link="link6"/>
        <child link="gripper_finger_link2"/>
        <origin xyz="${link6_length} 0.03 0" rpy="0 0 0" />
    </joint>

    <!-- RIGHT GRIPPER AFT LINK -->
    <link name="gripper_finger_link2">
        <visual>
            <origin xyz="${gripper_height/2} 0 0" rpy="0 ${M_PI/2} 0" />
            <geometry>
                <box size="${gripper_length} ${gripper_width} ${gripper_height}" />
            </geometry>
            <material name="White" />
        </visual>
        <collision>
            <origin xyz="${gripper_height/2} 0 0" rpy="0 ${M_PI/2} 0" />
            <geometry>
                <box size="${gripper_length} ${gripper_width} ${gripper_height}" />
            </geometry>
        </collision>
        <inertial>
            <origin xyz="${gripper_height/2} 0 0" rpy="0 ${M_PI/2} 0" />
            <mass value="${gripper_mass}" />
            <inertia ixx="${gripper_mass * (gripper_width ** 2 + gripper_height ** 2) / 12}" ixy="0" ixz="0" iyy="${gripper_mass * (gripper_length ** 2 + gripper_height ** 2) / 12}" iyz="0" izz="${gripper_mass * (gripper_length ** 2 + gripper_width ** 2) / 12}" />
        </inertial>
    </link>

    <!-- Grasping frame -->
    <link name="grasping_frame">
        <inertial>
            <origin xyz="0 0 0" rpy="0 0 0" />
            <mass value="0.01" />
            <inertia ixx="0.00001" ixy="0" ixz="0" iyy="0.00001" iyz="0" izz="0.00001" />
        </inertial>
    </link>

    <joint name="grasping_frame_joint" type="fixed">
        <parent link="link6"/>
        <child link="grasping_frame"/>
        <origin xyz="${gripper_height} 0 0" rpy="0 0 0"/>
    </joint>

    <!-- ros2_control configuration -->
    <ros2_control name="marm_robot" type="system">
        <hardware>
            <!-- 完全使用软件仿真时使用此插件 -->
            <!-- <plugin>mock_components/GenericSystem</plugin>  -->

            <!-- gazebo仿真时使用此插件 -->
            <plugin>gz_ros2_control/GazeboSimSystem</plugin>
        </hardware>
        <joint name="joint1">
            <command_interface name="position"/>
            <state_interface name="position"/>
        </joint>
        <joint name="joint2">
            <command_interface name="position"/>
            <state_interface name="position"/>
        </joint>
        <joint name="joint3">
            <command_interface name="position"/>
            <state_interface name="position"/>
        </joint>
        <joint name="joint4">
            <command_interface name="position"/>
            <state_interface name="position"/>
        </joint>
        <joint name="joint5">
            <command_interface name="position"/>
            <state_interface name="position"/>
        </joint>
        <joint name="joint6">
            <command_interface name="position"/>
            <state_interface name="position"/>
        </joint>
        <joint name="finger_joint1">
            <command_interface name="position"/>
            <state_interface name="position"/>
        </joint>
    </ros2_control>

    <!-- <xacro:macro name="transmission_block" params="joint_name">
        <ros2_control name="${joint_name}_system" type="actuator">
        <hardware>
            <plugin>mock_components/GenericSystem</plugin>
        </hardware>

        <joint name="${joint_name}">
            <command_interface name="position"/>
            <state_interface name="position"/>
            <state_interface name="velocity"/>
        </joint>
        </ros2_control>
    </xacro:macro>

    <xacro:transmission_block joint_name="joint1"/>
    <xacro:transmission_block joint_name="joint2"/>   
    <xacro:transmission_block joint_name="joint3"/>
    <xacro:transmission_block joint_name="joint4"/>
    <xacro:transmission_block joint_name="joint5"/>
    <xacro:transmission_block joint_name="joint6"/>
    <xacro:transmission_block joint_name="finger_joint1"/> -->

    <gazebo>
        <plugin name="gz_ros2_control::GazeboSimROS2ControlPlugin" filename="libgz_ros2_control-system.so">
            <parameters>$(find marm)/config/marm_ros2_controllers.yaml</parameters>
        </plugin>
    </gazebo>

    <gazebo reference="base_link">
        <material>Gazebo/White</material>
    </gazebo>

    <gazebo reference="link1">
        <material>Gazebo/Blue</material>
    </gazebo>

    <gazebo reference="link2">
        <material>Gazebo/White</material>
    </gazebo>

    <gazebo reference="link3">
        <material>Gazebo/Blue</material>
    </gazebo>

    <gazebo reference="link4">
        <material>Gazebo/Black</material>
    </gazebo>

    <gazebo reference="link5">
        <material>Gazebo/White</material>
    </gazebo>

    <gazebo reference="link6">
        <material>Gazebo/Blue</material>
    </gazebo>

    <gazebo reference="gripper_finger_link1">
        <material>Gazebo/White</material>
    </gazebo>

    <gazebo reference="gripper_finger_link2">
        <material>Gazebo/White</material>
    </gazebo>
</robot>

