<?xml version="1.0" ?>
<!-- =================================================================================== -->
<!-- |    This document was autogenerated by xacro from src/marm/urdf/arm.urdf.xacro   | -->
<!-- |    EDITING THIS FILE BY HAND IS NOT RECOMMENDED                                 | -->
<!-- =================================================================================== -->
<robot name="marm">
  <!-- Defining the colors used in this robot -->
  <material name="Black">
    <color rgba="0 0 0 1"/>
  </material>
  <material name="White">
    <color rgba="1 1 1 1"/>
  </material>
  <material name="Blue">
    <color rgba="0 0 1 1"/>
  </material>
  <material name="Red">
    <color rgba="1 0 0 1"/>
  </material>
  <!-- World link -->
  <link name="world"/>
  <!-- ////////////////////////////////////// ARM BASE ////////////////////////////////////// -->
  <joint name="world_arm_joint" type="fixed">
    <origin rpy="0 0 0" xyz="0 0 0"/>
    <parent link="world"/>
    <child link="base_link"/>
  </joint>
  <link name="base_link">
    <visual>
      <origin rpy="0 0 0" xyz="0 0 0"/>
      <geometry>
        <box size="0.001 0.001 0.001"/>
      </geometry>
    </visual>
    <collision>
      <geometry>
        <box size="0.001 0.001 0.001"/>
      </geometry>
    </collision>
    <inertial>
      <origin rpy="0 0 0" xyz="0 0 0"/>
      <mass value="0.1"/>
      <inertia ixx="0.0001" ixy="0" ixz="0" iyy="0.0001" iyz="0" izz="0.0001"/>
    </inertial>
  </link>
  <joint name="base_joint" type="fixed">
    <origin rpy="0 0 0" xyz="0 0 0.02"/>
    <parent link="base_link"/>
    <child link="link0"/>
  </joint>
  <!-- ////////////////////////////////////// LINK0 ////////////////////////////////////// -->
  <link name="link0">
    <visual>
      <origin rpy="0 0 0" xyz="0 0 0"/>
      <geometry>
        <cylinder length="0.04" radius="0.05"/>
      </geometry>
      <material name="White"/>
    </visual>
    <collision>
      <origin rpy="0 0 0" xyz="0 0 0"/>
      <geometry>
        <cylinder length="0.04" radius="0.05"/>
      </geometry>
    </collision>
    <inertial>
      <origin rpy="0 0 0" xyz="0 0 0"/>
      <mass value="1"/>
      <inertia ixx="0.0007583333333333335" ixy="0" ixz="0" iyy="0.0007583333333333335" iyz="0" izz="0.0012500000000000002"/>
    </inertial>
  </link>
  <joint name="joint1" type="revolute">
    <parent link="link0"/>
    <child link="link1"/>
    <origin rpy="0 1.570795 0" xyz="0 0 0.02"/>
    <axis xyz="-1 0 0"/>
    <limit effort="300" lower="-3.14159" upper="3.14159" velocity="1"/>
  </joint>
  <!-- ////////////////////////////////////// LINK1 ////////////////////////////////////// -->
  <link name="link1">
    <visual>
      <origin rpy="0 1.570795 0" xyz="-0.06 0 0"/>
      <geometry>
        <cylinder length="0.12" radius="0.03"/>
      </geometry>
      <material name="Blue"/>
    </visual>
    <collision>
      <origin rpy="0 1.570795 0" xyz="-0.06 0 0"/>
      <geometry>
        <cylinder length="0.12" radius="0.03"/>
      </geometry>
    </collision>
    <inertial>
      <origin rpy="0 1.570795 0" xyz="-0.06 0 0"/>
      <mass value="1"/>
      <inertia ixx="0.00045" ixy="0" ixz="0" iyy="0.001425" iyz="0" izz="0.001425"/>
    </inertial>
  </link>
  <joint name="joint2" type="revolute">
    <parent link="link1"/>
    <child link="link2"/>
    <origin rpy="-1.570795 0 1.570795" xyz="-0.12 0 0.0"/>
    <axis xyz="1 0 0"/>
    <limit effort="300" lower="-3.14159" upper="3.14159" velocity="1"/>
  </joint>
  <!-- ////////////////////////////////////// LINK2 ////////////////////////////////////// -->
  <link name="link2">
    <visual>
      <origin rpy="0 0 0" xyz="0 0 0.07"/>
      <geometry>
        <cylinder length="0.14" radius="0.03"/>
      </geometry>
      <material name="White"/>
    </visual>
    <collision>
      <origin rpy="0 0 0" xyz="0 0 0.07"/>
      <geometry>
        <cylinder length="0.14" radius="0.03"/>
      </geometry>
    </collision>
    <inertial>
      <origin rpy="0 0 0" xyz="0 0 0.07"/>
      <mass value="0.8"/>
      <inertia ixx="0.0014866666666666672" ixy="0" ixz="0" iyy="0.0014866666666666672" iyz="0" izz="0.00036"/>
    </inertial>
  </link>
  <joint name="joint3" type="revolute">
    <parent link="link2"/>
    <child link="link3"/>
    <origin rpy="0 3.14159 0" xyz="0 0 0.14"/>
    <axis xyz="-1 0 0"/>
    <limit effort="300" lower="-3.14159" upper="3.14159" velocity="1"/>
  </joint>
  <!-- ////////////////////////////////////// LINK3 ////////////////////////////////////// -->
  <link name="link3">
    <visual>
      <origin rpy="0 0 0" xyz="0 0 -0.075"/>
      <geometry>
        <cylinder length="0.15" radius="0.03"/>
      </geometry>
      <material name="Blue"/>
    </visual>
    <collision>
      <origin rpy="0 0 0" xyz="0 0 -0.075"/>
      <geometry>
        <cylinder length="0.15" radius="0.03"/>
      </geometry>
    </collision>
    <inertial>
      <origin rpy="0 0 0" xyz="0 0 -0.075"/>
      <mass value="0.8"/>
      <inertia ixx="0.00168" ixy="0" ixz="0" iyy="0.00168" iyz="0" izz="0.00036"/>
    </inertial>
  </link>
  <joint name="joint4" type="revolute">
    <parent link="link3"/>
    <child link="link4"/>
    <origin rpy="0 1.570795 3.14159" xyz="0.0 0.0 -0.15"/>
    <axis xyz="1 0 0"/>
    <limit effort="300" lower="-3.14159" upper="3.14159" velocity="1"/>
  </joint>
  <!-- ////////////////////////////////////// LINK4 ////////////////////////////////////// -->
  <link name="link4">
    <visual>
      <origin rpy="0 1.570795 0" xyz="0.03 0 0"/>
      <geometry>
        <cylinder length="0.06" radius="0.025"/>
      </geometry>
      <material name="Black"/>
    </visual>
    <collision>
      <origin rpy="0 1.570795 0" xyz="0.03 0 0"/>
      <geometry>
        <cylinder length="0.06" radius="0.025"/>
      </geometry>
    </collision>
    <inertial>
      <origin rpy="0 1.570795 0" xyz="0.03 0 0"/>
      <mass value="0.7"/>
      <inertia ixx="0.00021875000000000003" ixy="0" ixz="0" iyy="0.00031937500000000005" iyz="0" izz="0.00031937500000000005"/>
    </inertial>
  </link>
  <joint name="joint5" type="revolute">
    <parent link="link4"/>
    <child link="link5"/>
    <origin rpy="0 1.570795 0" xyz="0.06 0.0 0.0"/>
    <axis xyz="1 0 0"/>
    <limit effort="300" lower="-3.14159" upper="3.14159" velocity="1"/>
  </joint>
  <!-- ////////////////////////////////////// LINK5 ////////////////////////////////////// -->
  <link name="link5">
    <visual>
      <origin rpy="0 0 0" xyz="0 0 0.03"/>
      <geometry>
        <cylinder length="0.06" radius="0.03"/>
      </geometry>
      <material name="White"/>
    </visual>
    <collision>
      <origin rpy="0 0 0" xyz="0 0 0.03 "/>
      <geometry>
        <cylinder length="0.06" radius="0.03"/>
      </geometry>
    </collision>
    <inertial>
      <origin rpy="0 0 0" xyz="0 0 0.03"/>
      <mass value="0.7"/>
      <inertia ixx="0.0003675" ixy="0" ixz="0" iyy="0.0003675" iyz="0" izz="0.00031499999999999996"/>
    </inertial>
  </link>
  <joint name="joint6" type="revolute">
    <parent link="link5"/>
    <child link="link6"/>
    <origin rpy="4.712384999999999 -1.570795 0" xyz="0 0 0.06"/>
    <axis xyz="1 0 0"/>
    <limit effort="300" lower="-6.28318" upper="6.28318" velocity="1"/>
  </joint>
  <!-- ////////////////////////////////////// LINK6 ////////////////////////////////////// -->
  <link name="link6">
    <visual>
      <origin rpy="0 1.570795 0" xyz="0.01 0 0 "/>
      <geometry>
        <cylinder length="0.02" radius="0.04"/>
      </geometry>
      <material name="Blue"/>
    </visual>
    <collision>
      <origin rpy="0 1.570795 0" xyz="0.01 0 0"/>
      <geometry>
        <cylinder length="0.02" radius="0.04"/>
      </geometry>
    </collision>
    <inertial>
      <origin rpy="0 1.570795 0" xyz="0.01 0 0"/>
      <mass value="0.6"/>
      <inertia ixx="0.00048" ixy="0" ixz="0" iyy="0.00026000000000000003" iyz="0" izz="0.00026000000000000003"/>
    </inertial>
  </link>
  <joint name="finger_joint1" type="prismatic">
    <parent link="link6"/>
    <child link="gripper_finger_link1"/>
    <origin rpy="0 0 0" xyz="0.02 -0.03 0"/>
    <axis xyz="0 1 0"/>
    <limit effort="100" lower="0" upper="0.06" velocity="0.02"/>
  </joint>
  <!-- ////////////////////////////////////// gripper ////////////////////////////////////// -->
  <!-- LEFT GRIPPER AFT LINK -->
  <link name="gripper_finger_link1">
    <visual>
      <origin rpy="0 1.570795 0" xyz="0.03 0 0"/>
      <geometry>
        <box size="0.03 0.01 0.06"/>
      </geometry>
      <material name="White"/>
    </visual>
    <collision>
      <origin rpy="0 1.570795 0" xyz="0.03 0 0"/>
      <geometry>
        <box size="0.03 0.01 0.06"/>
      </geometry>
    </collision>
    <inertial>
      <origin rpy="0 1.570795 0" xyz="0.03 0 0"/>
      <mass value="0.5"/>
      <inertia ixx="0.00015416666666666666" ixy="0" ixz="0" iyy="0.00018749999999999998" iyz="0" izz="4.1666666666666665e-05"/>
    </inertial>
  </link>
  <joint name="finger_joint2" type="fixed">
    <parent link="link6"/>
    <child link="gripper_finger_link2"/>
    <origin rpy="0 0 0" xyz="0.02 0.03 0"/>
  </joint>
  <!-- RIGHT GRIPPER AFT LINK -->
  <link name="gripper_finger_link2">
    <visual>
      <origin rpy="0 1.570795 0" xyz="0.03 0 0"/>
      <geometry>
        <box size="0.03 0.01 0.06"/>
      </geometry>
      <material name="White"/>
    </visual>
    <collision>
      <origin rpy="0 1.570795 0" xyz="0.03 0 0"/>
      <geometry>
        <box size="0.03 0.01 0.06"/>
      </geometry>
    </collision>
    <inertial>
      <origin rpy="0 1.570795 0" xyz="0.03 0 0"/>
      <mass value="0.5"/>
      <inertia ixx="0.00015416666666666666" ixy="0" ixz="0" iyy="0.00018749999999999998" iyz="0" izz="4.1666666666666665e-05"/>
    </inertial>
  </link>
  <!-- Grasping frame -->
  <link name="grasping_frame">
    <inertial>
      <origin rpy="0 0 0" xyz="0 0 0"/>
      <mass value="0.01"/>
      <inertia ixx="0.00001" ixy="0" ixz="0" iyy="0.00001" iyz="0" izz="0.00001"/>
    </inertial>
  </link>
  <joint name="grasping_frame_joint" type="fixed">
    <parent link="link6"/>
    <child link="grasping_frame"/>
    <origin rpy="0 0 0" xyz="0.06 0 0"/>
  </joint>
  <!-- ros2_control configuration -->
  <ros2_control name="marm_robot" type="system">
    <hardware>
      <!-- 完全使用软件仿真时使用此插件 -->
      <!-- <plugin>mock_components/GenericSystem</plugin>  -->
      <!-- gazebo仿真时使用此插件 -->
      <plugin>gz_ros2_control/GazeboSimSystem</plugin>
    </hardware>
    <joint name="joint1">
      <command_interface name="position"/>
      <state_interface name="position"/>
    </joint>
    <joint name="joint2">
      <command_interface name="position"/>
      <state_interface name="position"/>
    </joint>
    <joint name="joint3">
      <command_interface name="position"/>
      <state_interface name="position"/>
    </joint>
    <joint name="joint4">
      <command_interface name="position"/>
      <state_interface name="position"/>
    </joint>
    <joint name="joint5">
      <command_interface name="position"/>
      <state_interface name="position"/>
    </joint>
    <joint name="joint6">
      <command_interface name="position"/>
      <state_interface name="position"/>
    </joint>
    <joint name="finger_joint1">
      <command_interface name="position"/>
      <state_interface name="position"/>
    </joint>
  </ros2_control>
  <!-- <xacro:macro name="transmission_block" params="joint_name">
        <ros2_control name="${joint_name}_system" type="actuator">
        <hardware>
            <plugin>mock_components/GenericSystem</plugin>
        </hardware>

        <joint name="${joint_name}">
            <command_interface name="position"/>
            <state_interface name="position"/>
            <state_interface name="velocity"/>
        </joint>
        </ros2_control>
    </xacro:macro>

    <xacro:transmission_block joint_name="joint1"/>
    <xacro:transmission_block joint_name="joint2"/>   
    <xacro:transmission_block joint_name="joint3"/>
    <xacro:transmission_block joint_name="joint4"/>
    <xacro:transmission_block joint_name="joint5"/>
    <xacro:transmission_block joint_name="joint6"/>
    <xacro:transmission_block joint_name="finger_joint1"/> -->
  <gazebo>
    <plugin filename="libgz_ros2_control-system.so" name="gz_ros2_control::GazeboSimROS2ControlPlugin">
      <parameters>/home/hl/marm_ws/install/marm/share/marm/config/marm_ros2_controllers.yaml</parameters>
    </plugin>
  </gazebo>
  <gazebo reference="base_link">
    <material>Gazebo/White</material>
  </gazebo>
  <gazebo reference="link1">
    <material>Gazebo/Blue</material>
  </gazebo>
  <gazebo reference="link2">
    <material>Gazebo/White</material>
  </gazebo>
  <gazebo reference="link3">
    <material>Gazebo/Blue</material>
  </gazebo>
  <gazebo reference="link4">
    <material>Gazebo/Black</material>
  </gazebo>
  <gazebo reference="link5">
    <material>Gazebo/White</material>
  </gazebo>
  <gazebo reference="link6">
    <material>Gazebo/Blue</material>
  </gazebo>
  <gazebo reference="gripper_finger_link1">
    <material>Gazebo/White</material>
  </gazebo>
  <gazebo reference="gripper_finger_link2">
    <material>Gazebo/White</material>
  </gazebo>
</robot>
